<?xml version="1.0"?>
<robot name="first_robot">
<!-- note: units are meters, kilograms, and radians -->
    <link name="base_link">
        <inertial>
            <origin rpy="0 0 0" xyz="0 0 0"/>
            <mass value="4.11" />
            <inertia ixx="0.1" ixy="0" ixz="0" iyy="0.62" iyz="0" izz="0.52"/>
             <!-- values taken from solidworks  -->
        </inertial>

        <collision>
            <origin rpy="0 0 0" xyz="0 0 0"/>
            <geometry>
                <box size="1 .38 .03"/>
                <!-- need a simple mesh box with a hole for future -> mining system -->
            </geometry>
        </collision>

        <visual>
            <origin rpy="0 0 0" xyz="0 0 0"/>
            <geometry>
                <mesh filename="package://moony_description/models/meshes/frame.dae"/>
            </geometry>
            <!-- <material name="green"/> -->
        </visual>
    </link>

    <gazebo reference="base_link">
        <kp>100000.0</kp>
        <kd>100000.0</kd>
        <mu1>10.0</mu1> 
        <mu2>10.0</mu2>
        <!-- <material>Gazebo/Grey</material> -->
    </gazebo>

    <link name="wheel_1_link">
        <inertial>
            <origin rpy="0 0 0" xyz="0 0 0"/>
            <mass value="2" />
            <inertia ixx="0.02" ixy="0" ixz="0" iyy="0.02" iyz="0" izz="0.04"/>
             <!-- values taken from solidworks; the origin is the position of the part
                w.r.t its axes for the second moment of mass values  -->
        </inertial>

        <collision>
            <origin rpy="0 0 0" xyz="0 0 0"/> <!-- center of the wheel -->
            <geometry>
                <cylinder radius="0.125" length="0.03125"/>
            </geometry>
        </collision>

        <visual>
            <origin rpy="0 0 0" xyz="0 0 0"/> <!-- center of the wheel -->
            <geometry>
                <mesh filename="package://moony_description/models/meshes/wheel.dae"/>
            </geometry>
            <!-- <material name="white"/> only used in rviz for simple geometry -->
        </visual>
    </link>
    
    <gazebo reference="wheel_1_link">
        <kp>100000.0</kp>
        <kd>100000.0</kd>
        <mu1>10.0</mu1> 
        <mu2>10.0</mu2>
        <!-- <material>Gazebo/Yellow</material> -->
    </gazebo>

    <joint name="wheel_1_joint" type="continuous">
        <parent link="base_link"/>
        <child link="wheel_1_link"/>
        <origin xyz="0.3 0.24 0" rpy="-1.57 0 0"/> <!-- joint location -->
        <!-- y = width/2 of frame + wheel COG to wall = .38/2 + .04 = .23 -->
        <limit effort="0.1" velocity="0.01"/>
        <axis xyz="0 1 0"/>
    </joint>

 </robot>

 <!-- LESSONS
 this error: "Spawn service failed. Exiting."
    was caused by: the mesh models trying to access the package "nasa_rmc" which was renamed to "moony_description"

this error: gazebo model NEVER appearing
    was caused by: accidental typed "inertial" within the inertial tag when it should have been "inertia"
 
 -->