<?xml version="1.0"?>
<robot name="first_robot">
<!-- note: units are meters, kilograms, and radians -->
    <material name="blue">
        <color rgba="0 0 0.8 1"/>
    </material>
    <material name="red">
        <color rgba="0.8 0 0 1"/>
    </material>
    <material name="green">
        <color rgba="0 0.8 0 1"/>
    </material>
    <material name="grey">
        <color rgba="0.75 0.75 0.75 1"/>
    </material>
    <material name="white">
        <color rgba="1.0 1.0 1.0 1"/>
    </material>
    <material name="black">
        <color rgba="0 0 0 1"/>
    </material>

    <link name="dummy">
    </link>

    <link name="base_link">
        <!-- <inertial>
            <origin rpy="0 0 0" xyz="0 0 0"/>
            <mass value="4.11" />
            <inertial ixx="0.1" ixy="0" ixz="0" iyy="0.62" iyz="0" izz="0.52"/>
             values taken from solidworks 
        </inertial> -->
        <visual>
            <origin rpy="0 0 0" xyz="0 0 0"/>
            <geometry>
                <!-- <box size="1 .38 .03"/> -->
                <mesh filename="package://moony_description/models/meshes/frame.dae"/>
            </geometry>
            <material name="green"/>
        </visual>
    </link>
    
    <joint name="dummy_joint" type="fixed">
        <parent link="dummy"/>
        <child link="base_link"/>
    </joint>

    <link name="wheel_1_link">
        <!-- <inertial>
            <origin rpy="0 0 0" xyz="0 0 0"/>
            <mass value="2" />
            <inertial ixx="0.02" ixy="0" ixz="0" iyy="0.02" iyz="0" izz="0.04"/>
             values taken from solidworks 
        </inertial> -->
        <visual>
            <origin rpy="-1.57 0 0" xyz="0 0 0"/> <!-- center of the wheel -->
            <geometry>
                <!-- <cylinder radius="0.125" length="0.03125"/> -->
                <mesh filename="package://moony_description/models/meshes/wheel.dae"/>
            </geometry>
            <material name="black"/>
        </visual>
    </link>
    
    <joint name="wheel_1_joint" type="continuous">
        <parent link="base_link"/>
        <child link="wheel_1_link"/>
        <origin xyz="0.3 0.24 0" rpy="0 0 0"/> <!-- joint location -->
        <!-- width/2 of frame + wheel COG to wall = .38/2 + .04 = .23 -->
        <limit effort="0.1" velocity="0.01"/>
        <axis xyz="0 1 0"/>
    </joint>

    <link name="wheel_2_link">
        <visual>
            <origin rpy="-1.57 0 0" xyz="0 0 0"/> <!-- center of the wheel -->
            <geometry>
                <!-- <cylinder radius="0.125" length="0.03125"/> -->
                <mesh filename="package://moony_description/models/meshes/wheel.dae"/>
            </geometry>
            <material name="black"/>
        </visual>
    </link>
    
    <joint name="wheel_2_joint" type="continuous">
        <parent link="base_link"/>
        <child link="wheel_2_link"/>
        <origin xyz="-0.3 0.24 0" rpy="0 0 0"/> <!-- joint location -->
        <limit effort="0.1" velocity="0.01"/>
        <axis xyz="0 1 0"/>
    </joint>
    
    <link name="wheel_3_link">
        <visual>
            <origin rpy="1.57 0 0" xyz="0 0 0"/> <!-- center of the wheel -->
            <geometry>
                <!-- <cylinder radius="0.125" length="0.03125"/> -->
                <mesh filename="package://moony_description/models/meshes/wheel.dae"/>
            </geometry>
            <material name="black"/>
        </visual>
    </link>
    
    <joint name="wheel_3_joint" type="continuous">
        <parent link="base_link"/>
        <child link="wheel_3_link"/>
        <origin xyz="0.3 -0.24 0" rpy="0 0 0"/> <!-- joint location -->
        <limit effort="0.1" velocity="0.01"/>
        <axis xyz="0 1 0"/>
    </joint>

    <link name="wheel_4_link">
        <visual>
            <origin rpy="1.57 0 0" xyz="0 0 0"/> <!-- center of the wheel -->
            <geometry>
                <!-- <cylinder radius="0.125" length="0.03125"/> -->
                <mesh filename="package://moony_description/models/meshes/wheel.dae"/>
            </geometry>
            <material name="black"/>
        </visual>
    </link>
    
    <joint name="wheel_4_joint" type="continuous">
        <parent link="base_link"/>
        <child link="wheel_4_link"/>
        <origin xyz="-0.3 -0.24 0" rpy="0 0 0"/> <!-- joint location -->
        <limit effort="0.1" velocity="0.01"/>
        <axis xyz="0 1 0"/>
    </joint>
</robot>
